Workbook

Sheet DB
A1: Site ID Code | B1: 2G Site ID | C1: 3G Site ID | D1: 4G ID | E1: 5G ID | F1: Power Type | G1: BB Status | H1: EOL Gen | I1: Site Owner | J1: Connectivity | K1: Regions | L1: Obsolete AC | M1: Obsolete Rectifier | N1: Obsolete Fire | O1: White List | P1: MC Name | Q1: White List Remarks | R1: Suffix
A2: RYQS0578 | B2: RYQS2M1578 | C2: RYQS2M3578 | D2: RYQS2M7578 | F2: SCECO | G2: Vandalized | H2: NA | I2: Zain | J2: Hub site (More than 05 Sites) | K2: R2 | L2: No | M2: Yes | N2: NO | O2: No | P2: rumah | Q2: -
A3: QRY2605 | B3: QRY2M2605 | C3: QRY2M4605 | D3: QRY2M8605 | F3: SCECO | G3: Vandalized | H3: NA | I3: Zain | J3: Less than 5 Sites | K3: R1 | L3: Yes | M3: Yes | N3: NA | O3: Yes | P3: Sakaka | Q3: AC Obsolete
A4: DAM0117 | B4: DAM2M1117 | C4: DAM2M3117 | D4: DAM2M7117 | E4: DAM2MN0117 | F4: SCECO | G4: Vandalized | H4: NA | I4: Zain | J4: Less than 5 Sites | K4: R1 | L4: No | M4: Yes | N4: No | O4: No | P4: Dammam | Q4: -
A5: SAK0585 | B5: SAK2M1585 | C5: SAK2M3585 | D5: SAK2M7585 | E5: SAK2MN0585 | F5: Co-located | G5: Weak | H5: NA | I5: Zain | J5: Core list | K5: R1 | L5: No | M5: Yes | N5: No | O5: No | P5: Sakaka | Q5: -
A6: JBL0465 | B6: JBL2M1465 | C6: JBL2M3465 | D6: JBL2M7465 | E6: JBL2MN0465 | F6: Co-located | G6: Good | H6: NA | I6: Zain | J6: Core list | K6: R1 | L6: No | M6: Yes | N6: No | O6: No | P6: Jubil | Q6: -
A7: SAK2953 | B7: SAK2M2953 | C7: SAK2M4953 | F7: SCECO | G7: Dead | H7: NA | I7: Zain | J7: Less than 5 Sites | K7: R1 | L7: Yes | M7: Yes | N7: NA | O7: Yes | P7: Sakaka | Q7: AC Obsolete
A8: ARR0518 | B8: ARR2M1518 | C8: ARR2M3518 | D8: ARR2M7518 | E8: ARR2MN0518 | F8: Co-located | G8: Weak | H8: NA | I8: Zain | J8: Core list | K8: R1 | L8: No | M8: Yes | N8: No | O8: No | P8: Sakaka | Q8: -
A9: KKM2164 | B9: KKM2M2164 | C9: KKM2M4164 | D9: KKM2M8164 | F9: SCECO | G9: Dead | H9: NA | I9: Zain | J9: Less than 5 Sites | K9: R1 | L9: Yes | M9: Yes | N9: NA | O9: Yes | P9: Hafr EL Batin | Q9: AC Obsolete
A10: DAM0232 | B10: DAM2M1232 | C10: DAM2M3232 | D10: DAM2M7232 | E10: DAM2MN0232 | F10: SCECO | G10: Vandalized | H10: NA | I10: Zain | J10: Less than 5 Sites | K10: R1 | L10: No | M10: No | N10: NA | O10: No | P10: Dammam | Q10: -
A11: SKQR0522 | B11: SKQR2M5522 | F11: Generator-SG | G11: Dead | H11: Yes | I11: Zain | J11: Less than 5 Sites | K11: R1 | L11: Yes | M11: Yes | N11: NA | O11: Yes | P11: Sakaka | Q11: AC Obsolete
A12: ARM0712 | B12: ARM2M1712 | C12: ARM2M3712 | D12: ARM2M7712 | F12: SCECO | G12: Dead | H12: NA | I12: Zain | J12: Less than 5 Sites | K12: R1 | L12: No | M12: Yes | N12: No | O12: No | P12: Dammam | Q12: -
A13: KKM2171 | B13: KKM2M2171 | C13: KKM2M4171 | D13: KKM2M8171 | F13: SCECO | G13: Vandalized | H13: NA | I13: Zain | J13: Less than 5 Sites | K13: R1 | L13: Yes | M13: Yes | N13: NA | O13: Yes | P13: Hafr EL Batin | Q13: AC Obsolete
A14: ARM0713 | B14: ARM2M1713 | C14: ARM2M3713 | D14: ARM2M7713 | E14: ARM2MN0713 | F14: SCECO | G14: New BB | H14: NA | I14: Zain | J14: Less than 5 Sites | K14: R1 | L14: No | M14: Yes | N14: No | O14: No | P14: Dammam | Q14: -
A15: KKM2168 | B15: KKM2M2168 | C15: KKM2M4168 | D15: KKM2M8168 | F15: SCECO | G15: Vandalized | H15: NA | I15: Zain | J15: Less than 5 Sites | K15: R1 | L15: Yes | M15: Yes | N15: NA | O15: Yes | P15: Hafr EL Batin | Q15: AC Obsolete
A16: DBQL0262 | B16: DBQL2M5262 | F16: Generator-SG | G16: New BB | H16: Yes | I16: Zain | J16: Less than 5 Sites | K16: R3 | L16: No | M16: No | O16: No | P16: Tabuk | Q16: -
A17: KKM2170 | B17: KKM2M2170 | C17: KKM2M4170 | D17: KKM2M8170 | F17: SCECO | G17: Vandalized | H17: NA | I17: Zain | J17: Less than 5 Sites | K17: R1 | L17: Yes | M17: Yes | N17: NA | O17: Yes | P17: Hafr EL Batin | Q17: AC Obsolete
A18: ARM0715 | B18: ARM2M1715 | C18: ARM2M3715 | D18: ARM2M7715 | F18: SCECO | G18: Dead | H18: NA | I18: Zain | J18: Less than 5 Sites | K18: R1 | L18: No | M18: Yes | N18: NA | O18: No | P18: Dammam | Q18: -
A19: RAF2580 | B19: RAF2M2580 | C19: RAF2M4580 | D19: RAF2M8580 | F19: SCECO | G19: Vandalized | H19: NA | I19: Zain | J19: Less than 5 Sites | K19: R1 | L19: Yes | M19: Yes | N19: NA | O19: Yes | P19: Hafr EL Batin | Q19: AC Obsolete
A20: RIY0762 | B20: RIY2M1762 | D20: RIY2M7762 | E20: RIY2MN0762 | F20: SCECO | G20: Vandalized | H20: NA | I20: Zain | J20: Less than 5 Sites | K20: R2 | L20: No | M20: No | N20: NO | O20: No | P20: riyadh | Q20: -
A21: KFKM0789 | B21: KFKM2M5789 | F21: Generator-SG | G21: Vandalized | H21: No | I21: Zain | J21: Less than 5 Sites | K21: R1 | L21: Yes | M21: Yes | N21: NA | O21: Yes | P21: Hafr EL Batin | Q21: AC Obsolete
A22: RIY2701 | B22: RIY2M2701 | D22: RIY2M8701 | E22: RIY2MN2701 | F22: SCECO | G22: Weak | H22: NA | I22: Zain | J22: VIP&SPL Monitor | K22: R2 | L22: No | M22: No | N22: NA (ODC) | O22: No | P22: riyadh | Q22: -
A23: KFKM0790 | B23: KFKM2M5790 | F23: Generator-SG | G23: Vandalized | H23: No | I23: Zain | J23: Less than 5 Sites | K23: R1 | L23: Yes | M23: Yes | N23: NA | O23: Yes | P23: Hafr EL Batin | Q23: AC Obsolete
A24: RIY2011 | B24: RIY2M2011 | D24: RIY2M8011 | E24: RIY2MN2011 | F24: SCECO | G24: Vandalized | H24: NA | I24: Zain | J24: Less than 5 Sites | K24: R2 | L24: No | M24: No | N24: NO | O24: No | P24: riyadh | Q24: -
A25: KFKM0791 | B25: KFKM2M5791 | F25: Generator-SG | G25: Vandalized | H25: No | I25: Zain | J25: Less than 5 Sites | K25: R1 | L25: Yes | M25: Yes | N25: NA | O25: Yes | P25: Hafr EL Batin | Q25: AC Obsolete
A26: DBQL0264 | B26: DBQL2M5264 | F26: Generator-SG | G26: Vandalized | H26: No | I26: Zain | J26: Less than 5 Sites | K26: R3 | L26: Vandalized | M26: Yes | O26: Yes | P26: Tabuk | Q26: AC Vandalism case
A27: KFKM0793 | B27: KFKM2M5793 | F27: Generator-SG | G27: Vandalized | H27: No | I27: Zain | J27: Less than 5 Sites | K27: R1 | L27: Yes | M27: Yes | N27: NA | O27: Yes | P27: Hafr EL Batin | Q27: AC Obsolete | R27: Hub Site
A28: HQL2038 | B28: HQL2M2038 | C28: HQL2M4038 | D28: HQL2M8038 | F28: SCECO | G28: Dead | H28: NA | I28: Zain | J28: Less than 5 Sites | K28: R3 | L28: No | M28: Yes | O28: No | P28: Tabuk | Q28: -
A29: SMN0800 | B29: SMN2M5800 | F29: SCECO | G29: Vandalized | H29: NA | I29: Zain | J29: Less than 5 Sites | K29: R1 | L29: Yes | M29: Yes | N29: NA | O29: Yes | P29: Hafr EL Batin | Q29: AC Obsolete
A30: ARR0653 | B30: ARR2M1653 | C30: ARR2M3653 | D30: ARR2M7653 | E30: ARR2MN0653 | F30: SCECO | G30: Good | H30: NA | I30: Zain | J30: Less than 5 Sites | K30: R1 | L30: No | M30: No | N30: NA | O30: No | P30: Sakaka | Q30: -
A31: SMN0801 | B31: SMN2M5801 | F31: Generator-SG | G31: Vandalized | H31: No | I31: Zain | J31: Less than 5 Sites | K31: R1 | L31: Yes | M31: Yes | N31: NA | O31: Yes | P31: Hafr EL Batin | Q31: AC Obsolete
A32: ARR0656 | B32: ARR2M1656 | C32: ARR2M3656 | D32: ARR2M7656 | E32: ARR2MN0656 | F32: SCECO | G32: Good | H32: NA | I32: Zain | J32: Less than 5 Sites | K32: R1 | L32: No | M32: No | N32: NA | O32: No | P32: Sakaka | Q32: -
A33: SMRY0809 | B33: SMRY2M5809 | F33: Generator-SG | G33: Vandalized | H33: No | I33: Zain | J33: Less than 5 Sites | K33: R1 | L33: Yes | M33: Yes | N33: NA | O33: Yes | P33: Hafr EL Batin | Q33: AC Obsolete
A34: DAM0118 | B34: DAM2M1118 | C34: DAM2M3118 | D34: DAM2M7118 | E34: DAM2MN0118 | F34: SCECO | G34: Vandalized | H34: NA | I34: Zain | J34: Less than 5 Sites | K34: R1 | L34: No | M34: Yes | N34: No | O34: No | P34: Dammam | Q34: -
A35: KFKM0781 | B35: KFKM2M5781 | F35: Generator-SG | G35: Vandalized | H35: Yes | I35: Zain | J35: Less than 5 Sites | K35: R1 | L35: Yes | M35: Yes | N35: NA | O35: Yes | P35: Jubail | Q35: AC Obsolete
A36: DAM0210 | B36: DAM2M1210 | C36: DAM2M3210 | D36: DAM2M7210 | E36: DAM2MN0210 | F36: SCECO | G36: Vandalized | H36: NA | I36: Zain | J36: Less than 5 Sites | K36: R1 | L36: No | M36: No | N36: Working | O36: No | P36: Dammam | Q36: -
A37: KFKM0782 | B37: KFKM2M5782 | F37: Generator-SG | G37: Vandalized | H37: No | I37: Zain | J37: Less than 5 Sites | K37: R1 | L37: Yes | M37: Yes | N37: NA | O37: Yes | P37: Jubail | Q37: AC Obsolete
A38: DAM0212 | B38: DAM2M1212 | C38: DAM2M3212 | D38: DAM2M7212 | E38: DAM2MN0212 | F38: SCECO | G38: Vandalized | H38: NA | I38: Zain | J38: Less than 5 Sites | K38: R1 | L38: Vandalized | M38: Yes | N38: No | O38: Yes | P38: Dammam | Q38: AC Vandalism case
A39: KKM2161 | B39: KKM2M2161 | C39: KKM2M4161 | D39: KKM2M8161 | F39: SCECO | G39: Dead | H39: NA | I39: Zain | J39: Less than 5 Sites | K39: R1 | L39: Yes | M39: Yes | N39: NA | O39: Yes | P39: Hafr EL Batin | Q39: AC Obsolete
A40: DAM0332 | B40: DAM2M1332 | C40: DAM2M3332 | D40: DAM2M7332 | F40: SCECO | G40: Dead | H40: NA | I40: Zain | J40: VIP&SPL Monitor | K40: R1 | L40: No | M40: No | N40: NA | O40: No | P40: Dammam | Q40: -
...

Sheet R1
A1: PCM | B1: Region | C1: Count sites | D1: Hub Site | E1: Fault Level | F1: PCM Created At | G1: Elapsed Duration(Hrs) | H1: Creat Fault First Time Occured | I1: Power Source | J1: Battery Backup Status | K1: EM Field Feedback | L1: Site Owner
A2: PCM-20250105-00002270 | B2: =IFERROR(VLOOKUP(D2,DB!A:K,11,0),"") -> R1 | C2: 1 | D2: JBL2138 | E2: Major | F2: 45662.948 | G2: =IFERROR(NOW()-F2,"") -> 268.1327 | H2: 45662.943 | I2: =IFERROR(VLOOKUP(D2,DB!A:F,6,0),"") -> Generator-SG | J2: =IFERROR(VLOOKUP(D2,DB!A:G,7,0),"") -> Dead | K2: as per RC Director of Investors Authority feedback the Facilities Management refused to open the gate, we already requested official letter and support to open the gate, but still no response, Saudi responsible follow up with them to get officially feedback. | L2: =IFERROR(VLOOKUP(D2,DB!A:I,9,0),"") -> Latis
A3: PCM-20250916-00001827 | B3: =IFERROR(VLOOKUP(D3,DB!A:K,11,0),"") -> R1 | C3: 2 | D3: DAM2066 | E3: Critical | F3: 45916.569 | G3: =IFERROR(NOW()-F3,"") -> 14.51172 | H3: 45916.569 | I3: =IFERROR(VLOOKUP(D3,DB!A:F,6,0),"") -> SCECO | J3: =IFERROR(VLOOKUP(D3,DB!A:G,7,0),"") -> Good | K3: Flapping down // Site located in university and team tried to enter but we have access issue escalated | L3: =IFERROR(VLOOKUP(D3,DB!A:I,9,0),"") -> Latis
B4: =IFERROR(VLOOKUP(D4,DB!A:K,11,0),"") | G4: =IFERROR(NOW()-F4,"") -> 45931.081 | I4: =IFERROR(VLOOKUP(D4,DB!A:F,6,0),"") | J4: =IFERROR(VLOOKUP(D4,DB!A:G,7,0),"") | L4: =IFERROR(VLOOKUP(D4,DB!A:I,9,0),"")
B5: =IFERROR(VLOOKUP(D5,DB!A:K,11,0),"") | G5: =IFERROR(NOW()-F5,"") -> 45931.081 | I5: =IFERROR(VLOOKUP(D5,DB!A:F,6,0),"") | J5: =IFERROR(VLOOKUP(D5,DB!A:G,7,0),"") | L5: =IFERROR(VLOOKUP(D5,DB!A:I,9,0),"")
B6: =IFERROR(VLOOKUP(D6,DB!A:K,11,0),"") | G6: =IFERROR(NOW()-F6,"") -> 45931.081 | I6: =IFERROR(VLOOKUP(D6,DB!A:F,6,0),"") | J6: =IFERROR(VLOOKUP(D6,DB!A:G,7,0),"") | L6: =IFERROR(VLOOKUP(D6,DB!A:I,9,0),"")
B7: =IFERROR(VLOOKUP(D7,DB!A:K,11,0),"") | G7: =IFERROR(NOW()-F7,"") -> 45931.081 | I7: =IFERROR(VLOOKUP(D7,DB!A:F,6,0),"") | J7: =IFERROR(VLOOKUP(D7,DB!A:G,7,0),"") | L7: =IFERROR(VLOOKUP(D7,DB!A:I,9,0),"")
B8: =IFERROR(VLOOKUP(D8,DB!A:K,11,0),"") | G8: =IFERROR(NOW()-F8,"") -> 45931.081 | I8: =IFERROR(VLOOKUP(D8,DB!A:F,6,0),"") | J8: =IFERROR(VLOOKUP(D8,DB!A:G,7,0),"") | L8: =IFERROR(VLOOKUP(D8,DB!A:I,9,0),"")
B9: =IFERROR(VLOOKUP(D9,DB!A:K,11,0),"") | G9: =IFERROR(NOW()-F9,"") -> 45931.081 | I9: =IFERROR(VLOOKUP(D9,DB!A:F,6,0),"") | J9: =IFERROR(VLOOKUP(D9,DB!A:G,7,0),"") | L9: =IFERROR(VLOOKUP(D9,DB!A:I,9,0),"")
B10: =IFERROR(VLOOKUP(D10,DB!A:K,11,0),"") | G10: =IFERROR(NOW()-F10,"") -> 45931.081 | I10: =IFERROR(VLOOKUP(D10,DB!A:F,6,0),"") | J10: =IFERROR(VLOOKUP(D10,DB!A:G,7,0),"") | L10: =IFERROR(VLOOKUP(D10,DB!A:I,9,0),"")
B11: =IFERROR(VLOOKUP(D11,DB!A:K,11,0),"") | G11: =IFERROR(NOW()-F11,"") -> 45931.081 | I11: =IFERROR(VLOOKUP(D11,DB!A:F,6,0),"") | J11: =IFERROR(VLOOKUP(D11,DB!A:G,7,0),"") | L11: =IFERROR(VLOOKUP(D11,DB!A:I,9,0),"")
B12: =IFERROR(VLOOKUP(D12,DB!A:K,11,0),"") | G12: =IFERROR(NOW()-F12,"") -> 45931.081 | I12: =IFERROR(VLOOKUP(D12,DB!A:F,6,0),"") | J12: =IFERROR(VLOOKUP(D12,DB!A:G,7,0),"") | L12: =IFERROR(VLOOKUP(D12,DB!A:I,9,0),"")
B13: =IFERROR(VLOOKUP(D13,DB!A:K,11,0),"") | G13: =IFERROR(NOW()-F13,"") -> 45931.081 | I13: =IFERROR(VLOOKUP(D13,DB!A:F,6,0),"") | J13: =IFERROR(VLOOKUP(D13,DB!A:G,7,0),"") | L13: =IFERROR(VLOOKUP(D13,DB!A:I,9,0),"")
B14: =IFERROR(VLOOKUP(D14,DB!A:K,11,0),"") | G14: =IFERROR(NOW()-F14,"") -> 45931.081 | I14: =IFERROR(VLOOKUP(D14,DB!A:F,6,0),"") | J14: =IFERROR(VLOOKUP(D14,DB!A:G,7,0),"") | L14: =IFERROR(VLOOKUP(D14,DB!A:I,9,0),"")
B15: =IFERROR(VLOOKUP(D15,DB!A:K,11,0),"") | G15: =IFERROR(NOW()-F15,"") -> 45931.081 | I15: =IFERROR(VLOOKUP(D15,DB!A:F,6,0),"") | J15: =IFERROR(VLOOKUP(D15,DB!A:G,7,0),"") | L15: =IFERROR(VLOOKUP(D15,DB!A:I,9,0),"")
... B83: =IFERROR(VLOOKUP(D83,DB!A:K,11,0),"") | G83: =IFERROR(NOW()-F83,"") -> 45931.081 | I83: =IFERROR(VLOOKUP(D83,DB!A:F,6,0),"") | J83: =IFERROR(VLOOKUP(D83,DB!A:G,7,0),"") | L83: =IFERROR(VLOOKUP(D83,DB!A:I,9,0),"")

Sheet R2
A1: PCM | B1: Region | C1: Count sites | D1: Hub Site | E1: Fault Level | F1: PCM Created At | G1: Elapsed Duration(Hrs) | H1: Creat Fault First Time Occured | I1: Power Source | J1: Battery Backup Status | K1: EM Field Feedback | L1: Site Owner | M1: Column1 | N1: Column2 | O1: Column3 | P1: Column4 | Q1: Column5 | R1: Column6 | S1: Column7 | T1: Column8 | U1: Column9 | V1: Column10 | W1: Column11 | X1: Column12 | Y1: Column13 | Z1: Column14 | AA1: Column15 | AB1: Column16 | AC1: Column17 | AD1: Column18 | AE1: Column19 | AF1: Column20 | AG1: Column21 | AH1: Column22 | AI1: Column23 | AJ1: Column24 | AK1: Column25 | AL1: Column26 | AM1: Column27 | AN1: Column28 | AO1: Column29 | AP1: Column30 | AQ1: Column31 | AR1: Column32 | AS1: Column33 | AT1: Column34 | AU1: Column35 | AV1: Column36 | AW1: Column37 | AX1: Column38 | AY1: Column39 | AZ1: Column40 | BA1: Column41 | BB1: Column42 | BC1: Column43 | BD1: Column44 | BE1: Column45 | BF1: Column46 | BG1: Column47 | BH1: Column48 | BI1: Column49 | BJ1: Column50 | BK1: Column51 | BL1: Column52 | BM1: Column53 | BN1: Column54 | BO1: Column55 | BP1: Column56 | BQ1: Column57 | BR1: Column58 | BS1: Column59 | BT1: Column60 | BU1: Column61 | BV1: Column62 | BW1: Column63 | BX1: Column64 | BY1: Column65 | BZ1: Column66 | CA1: Column67 | CB1: Column68 | CC1: Column69 | CD1: Column70 | CE1: Column71 | CF1: Column72 | CG1: Column73 | CH1: Column74 | CI1: Column75 | CJ1: Column76
A2: PCM-20250421-00001074 | B2: R2 | C2: 1 | D2: RIY2486 | E2: Critical | F2: 45322.057 | G2: 14276:43:42 | H2: 45322.051 | I2: Generator-SG | J2: Dead | K2: site located in VIP Area and Generator switched off as per security request. | L2: Latis
A3: PCM-20250203-00001501 | B3: =IFERROR(VLOOKUP(D3,DB!A:K,11,0),"") -> R2 | C3: 1 | D3: RIY2719 | E3: Critical | F3: 45691.652 | G3: =IFERROR(NOW()-F3,"-") -> 239.42935 | H3: 45691.646 | I3: =IFERROR(VLOOKUP(D3,DB!A:F,6,0),"") -> Generator-SG | J3: =IFERROR(VLOOKUP(D3,DB!A:G,7,0),"") -> Vandalized | K3: Access Issue As Site located inside Wonder Garden. | L3: =IFERROR(VLOOKUP(D3,DB!A:I,9,0),"") -> Latis
A4: PCM-20250529-00002138 | B4: =IFERROR(VLOOKUP(D4,DB!A:K,11,0),"") -> R2 | C4: 1 | D4: RIY2903 | E4: Major | F4: 45806.727 | G4: =IFERROR(NOW()-F4,"-") -> 124.35405 | H4: 45791.543 | I4: =IFERROR(VLOOKUP(D4,DB!A:F,6,0),"") -> SCECO | J4: =IFERROR(VLOOKUP(D4,DB!A:G,7,0),"") -> No BB Shifted | K4: We face access Issue Due Boulevard Gate , STC Owner , access PG | L4: =IFERROR(VLOOKUP(D4,DB!A:I,9,0),"") -> Latis
A5: PCM-20250616-00002875 | B5: =IFERROR(VLOOKUP(D5,DB!A:K,11,0),"") -> R2 | C5: 1 | D5: RIY0274 | E5: Major | F5: 45825 | G5: =IFERROR(NOW()-F5,"-") -> 106.08129 | H5: 45824.994 | I5: =IFERROR(VLOOKUP(D5,DB!A:F,6,0),"") -> Generator-SG | J5: =IFERROR(VLOOKUP(D5,DB!A:G,7,0),"") -> Good | K5: Site located inside Palace Access issue Escalated to SMT | L5: =IFERROR(VLOOKUP(D5,DB!A:I,9,0),"") -> Latis
A6: PCM-20250923-00000318 | B6: =IFERROR(VLOOKUP(D6,DB!A:K,11,0),"") -> R2 | C6: 1 | D6: RIY0338 | E6: Major | F6: 45923.226 | G6: =IFERROR(NOW()-F6,"-") -> 7.855563 | H6: 45923.145 | I6: =IFERROR(VLOOKUP(D6,DB!A:F,6,0),"") -> SCECO | J6: =IFERROR(VLOOKUP(D6,DB!A:G,7,0),"") -> In progress | K6: Cell Unavailable at RIY2M7338-P2-L800 @ Sceco // During the site visit our team faced an access issue our access team is checking with the owners once access is secured will visit the site | L6: =IFERROR(VLOOKUP(D6,DB!A:I,9,0),"") -> Latis
A7: PCM-20251001-00000015 | B7: =IFERROR(VLOOKUP(D7,DB!A:K,11,0),"") -> R2 | C7: 1 | D7: AFL0092 | E7: Major | F7: 45931.013 | G7: =IFERROR(NOW()-F7,"-") -> 0.068456481 | H7: 45931.008 | I7: =IFERROR(VLOOKUP(D7,DB!A:F,6,0),"") -> Power Cube | J7: =IFERROR(VLOOKUP(D7,DB!A:G,7,0),"") -> Good+No BB Design | K7: Site has access issue at night inside desert area. | L7: =IFERROR(VLOOKUP(D7,DB!A:I,9,0),"") -> Latis
B8: =IFERROR(VLOOKUP(D8,DB!A:K,11,0),"") | G8: =IFERROR(NOW()-F8,"-") -> 45931.081 | I8: =IFERROR(VLOOKUP(D8,DB!A:F,6,0),"") | J8: =IFERROR(VLOOKUP(D8,DB!A:G,7,0),"") | L8: =IFERROR(VLOOKUP(D8,DB!A:I,9,0),"")
B9: =IFERROR(VLOOKUP(D9,DB!A:K,11,0),"") | G9: =IFERROR(NOW()-F9,"-") -> 45931.081 | I9: =IFERROR(VLOOKUP(D9,DB!A:F,6,0),"") | J9: =IFERROR(VLOOKUP(D9,DB!A:G,7,0),"") | L9: =IFERROR(VLOOKUP(D9,DB!A:I,9,0),"")
B10: =IFERROR(VLOOKUP(D10,DB!A:K,11,0),"") | G10: =IFERROR(NOW()-F10,"-") -> 45931.081 | I10: =IFERROR(VLOOKUP(D10,DB!A:F,6,0),"") | J10: =IFERROR(VLOOKUP(D10,DB!A:G,7,0),"") | L10: =IFERROR(VLOOKUP(D10,DB!A:I,9,0),"")
B11: =IFERROR(VLOOKUP(D11,DB!A:K,11,0),"") | G11: =IFERROR(NOW()-F11,"-") -> 45931.081 | I11: =IFERROR(VLOOKUP(D11,DB!A:F,6,0),"") | J11: =IFERROR(VLOOKUP(D11,DB!A:G,7,0),"") | L11: =IFERROR(VLOOKUP(D11,DB!A:I,9,0),"")
B12: =IFERROR(VLOOKUP(D12,DB!A:K,11,0),"") | G12: =IFERROR(NOW()-F12,"-") -> 45931.081 | I12: =IFERROR(VLOOKUP(D12,DB!A:F,6,0),"") | J12: =IFERROR(VLOOKUP(D12,DB!A:G,7,0),"") | L12: =IFERROR(VLOOKUP(D12,DB!A:I,9,0),"")
B13: =IFERROR(VLOOKUP(D13,DB!A:K,11,0),"") | G13: =IFERROR(NOW()-F13,"-") -> 45931.081 | I13: =IFERROR(VLOOKUP(D13,DB!A:F,6,0),"") | J13: =IFERROR(VLOOKUP(D13,DB!A:G,7,0),"") | L13: =IFERROR(VLOOKUP(D13,DB!A:I,9,0),"")
B14: =IFERROR(VLOOKUP(D14,DB!A:K,11,0),"") | G14: =IFERROR(NOW()-F14,"-") -> 45931.081 | I14: =IFERROR(VLOOKUP(D14,DB!A:F,6,0),"") | J14: =IFERROR(VLOOKUP(D14,DB!A:G,7,0),"") | L14: =IFERROR(VLOOKUP(D14,DB!A:I,9,0),"")
B15: =IFERROR(VLOOKUP(D15,DB!A:K,11,0),"") | G15: =IFERROR(NOW()-F15,"-") -> 45931.081 | I15: =IFERROR(VLOOKUP(D15,DB!A:F,6,0),"") | J15: =IFERROR(VLOOKUP(D15,DB!A:G,7,0),"") | L15: =IFERROR(VLOOKUP(D15,DB!A:I,9,0),"")
B16: =IFERROR(VLOOKUP(D16,DB!A:K,11,0),"") | G16: =IFERROR(NOW()-F16,"-") -> 45931.081 | I16: =IFERROR(VLOOKUP(D16,DB!A:F,6,0),"") | J16: =IFERROR(VLOOKUP(D16,DB!A:G,7,0),"") | L16: =IFERROR(VLOOKUP(D16,DB!A:I,9,0),"")
B17: =IFERROR(VLOOKUP(D17,DB!A:K,11,0),"") | G17: =IFERROR(NOW()-F17,"-") -> 45931.081 | I17: =IFERROR(VLOOKUP(D17,DB!A:F,6,0),"") | J17: =IFERROR(VLOOKUP(D17,DB!A:G,7,0),"") | L17: =IFERROR(VLOOKUP(D17,DB!A:I,9,0),"")
B18: =IFERROR(VLOOKUP(D18,DB!A:K,11,0),"") | G18: =IFERROR(NOW()-F18,"-") -> 45931.081 | I18: =IFERROR(VLOOKUP(D18,DB!A:F,6,0),"") | J18: =IFERROR(VLOOKUP(D18,DB!A:G,7,0),"") | L18: =IFERROR(VLOOKUP(D18,DB!A:I,9,0),"")
B19: =IFERROR(VLOOKUP(D19,DB!A:K,11,0),"") | G19: =IFERROR(NOW()-F19,"-") -> 45931.081 | I19: =IFERROR(VLOOKUP(D19,DB!A:F,6,0),"") | J19: =IFERROR(VLOOKUP(D19,DB!A:G,7,0),"") | L19: =IFERROR(VLOOKUP(D19,DB!A:I,9,0),"")
... B21: =IFERROR(VLOOKUP(D21,DB!A:K,11,0),"") | G21: =IFERROR(NOW()-F21,"-") -> 45931.081 | I21: =IFERROR(VLOOKUP(D21,DB!A:F,6,0),"") | J21: =IFERROR(VLOOKUP(D21,DB!A:G,7,0),"") | L21: =IFERROR(VLOOKUP(D21,DB!A:I,9,0),"")

Sheet R3
A1: PCM | B1: Region | C1: Count sites | D1: Hub Site | E1: Fault Level | F1: PCM Created At | G1: Elapsed Duration(Hrs) | H1: Creat Fault First Time Occured | I1: Power Source | J1: Battery Backup Status | K1: EM Field Feedback | L1: Site Owner
B2: =IFERROR(VLOOKUP(D2,DB!A:K,11,0),"") | G2: =IFERROR(NOW()-F2,"-") -> 45931.081 | I2: =IFERROR(VLOOKUP(D2,DB!A:F,6,0),"") | J2: =IFERROR(VLOOKUP(D2,DB!A:G,7,0),"") | L2: =IFERROR(VLOOKUP(D2,DB!A:I,9,0),"")
B3: =IFERROR(VLOOKUP(D3,DB!A:K,11,0),"") | G3: =IFERROR(NOW()-F3,"-") -> 45931.081 | I3: =IFERROR(VLOOKUP(D3,DB!A:F,6,0),"") | J3: =IFERROR(VLOOKUP(D3,DB!A:G,7,0),"") | L3: =IFERROR(VLOOKUP(D3,DB!A:I,9,0),"")
B4: =IFERROR(VLOOKUP(D4,DB!A:K,11,0),"") | G4: =IFERROR(NOW()-F4,"-") -> 45931.081 | I4: =IFERROR(VLOOKUP(D4,DB!A:F,6,0),"") | J4: =IFERROR(VLOOKUP(D4,DB!A:G,7,0),"") | L4: =IFERROR(VLOOKUP(D4,DB!A:I,9,0),"")
B5: =IFERROR(VLOOKUP(D5,DB!A:K,11,0),"") | G5: =IFERROR(NOW()-F5,"-") -> 45931.081 | I5: =IFERROR(VLOOKUP(D5,DB!A:F,6,0),"") | J5: =IFERROR(VLOOKUP(D5,DB!A:G,7,0),"") | L5: =IFERROR(VLOOKUP(D5,DB!A:I,9,0),"")
B6: =IFERROR(VLOOKUP(D6,DB!A:K,11,0),"") | G6: =IFERROR(NOW()-F6,"-") -> 45931.081 | I6: =IFERROR(VLOOKUP(D6,DB!A:F,6,0),"") | J6: =IFERROR(VLOOKUP(D6,DB!A:G,7,0),"") | L6: =IFERROR(VLOOKUP(D6,DB!A:I,9,0),"")
B7: =IFERROR(VLOOKUP(D7,DB!A:K,11,0),"") | G7: =IFERROR(NOW()-F7,"-") -> 45931.081 | I7: =IFERROR(VLOOKUP(D7,DB!A:F,6,0),"") | J7: =IFERROR(VLOOKUP(D7,DB!A:G,7,0),"") | L7: =IFERROR(VLOOKUP(D7,DB!A:I,9,0),"")
B8: =IFERROR(VLOOKUP(D8,DB!A:K,11,0),"") | G8: =IFERROR(NOW()-F8,"-") -> 45931.081 | I8: =IFERROR(VLOOKUP(D8,DB!A:F,6,0),"") | J8: =IFERROR(VLOOKUP(D8,DB!A:G,7,0),"") | L8: =IFERROR(VLOOKUP(D8,DB!A:I,9,0),"")
B9: =IFERROR(VLOOKUP(D9,DB!A:K,11,0),"") | G9: =IFERROR(NOW()-F9,"-") -> 45931.081 | I9: =IFERROR(VLOOKUP(D9,DB!A:F,6,0),"") | J9: =IFERROR(VLOOKUP(D9,DB!A:G,7,0),"") | L9: =IFERROR(VLOOKUP(D9,DB!A:I,9,0),"")
B10: =IFERROR(VLOOKUP(D10,DB!A:K,11,0),"") | G10: =IFERROR(NOW()-F10,"-") -> 45931.081 | I10: =IFERROR(VLOOKUP(D10,DB!A:F,6,0),"") | J10: =IFERROR(VLOOKUP(D10,DB!A:G,7,0),"") | L10: =IFERROR(VLOOKUP(D10,DB!A:I,9,0),"")
B11: =IFERROR(VLOOKUP(D11,DB!A:K,11,0),"") | G11: =IFERROR(NOW()-F11,"-") -> 45931.081 | I11: =IFERROR(VLOOKUP(D11,DB!A:F,6,0),"") | J11: =IFERROR(VLOOKUP(D11,DB!A:G,7,0),"") | L11: =IFERROR(VLOOKUP(D11,DB!A:I,9,0),"")
B12: =IFERROR(VLOOKUP(D12,DB!A:K,11,0),"") | G12: =IFERROR(NOW()-F12,"-") -> 45931.081 | I12: =IFERROR(VLOOKUP(D12,DB!A:F,6,0),"") | J12: =IFERROR(VLOOKUP(D12,DB!A:G,7,0),"") | L12: =IFERROR(VLOOKUP(D12,DB!A:I,9,0),"")
B13: =IFERROR(VLOOKUP(D13,DB!A:K,11,0),"") | G13: =IFERROR(NOW()-F13,"-") -> 45931.081 | I13: =IFERROR(VLOOKUP(D13,DB!A:F,6,0),"") | J13: =IFERROR(VLOOKUP(D13,DB!A:G,7,0),"") | L13: =IFERROR(VLOOKUP(D13,DB!A:I,9,0),"")
... B17: =IFERROR(VLOOKUP(D17,DB!A:K,11,0),"") | G17: =IFERROR(NOW()-F17,"-") -> 45931.081 | I17: =IFERROR(VLOOKUP(D17,DB!A:F,6,0),"") | J17: =IFERROR(VLOOKUP(D17,DB!A:G,7,0),"") | L17: =IFERROR(VLOOKUP(D17,DB!A:I,9,0),"")
B18: =IFERROR(VLOOKUP(#REF!,DB!A:K,11,0),"") | G18: =IFERROR(NOW()-#REF!,"-") -> - | I18: =IFERROR(VLOOKUP(#REF!,DB!A:F,6,0),"") | J18: =IFERROR(VLOOKUP(#REF!,DB!A:G,7,0),"") | L18: =IFERROR(VLOOKUP(#REF!,DB!A:I,9,0),"")
B19: =IFERROR(VLOOKUP(D19,DB!A:K,11,0),"") | G19: =IFERROR(NOW()-F19,"-") -> 45931.081 | I19: =IFERROR(VLOOKUP(D19,DB!A:F,6,0),"") | J19: =IFERROR(VLOOKUP(D19,DB!A:G,7,0),"") | L19: =IFERROR(VLOOKUP(D19,DB!A:I,9,0),"")
B20: =IFERROR(VLOOKUP(D20,DB!A:K,11,0),"") | G20: =IFERROR(NOW()-F20,"-") -> 45931.081 | I20: =IFERROR(VLOOKUP(D20,DB!A:F,6,0),"") | J20: =IFERROR(VLOOKUP(D20,DB!A:G,7,0),"") | L20: =IFERROR(VLOOKUP(D20,DB!A:I,9,0),"")
B21: =IFERROR(VLOOKUP(D21,DB!A:K,11,0),"") | G21: =IFERROR(NOW()-F21,"-") -> 45931.081 | I21: =IFERROR(VLOOKUP(D21,DB!A:F,6,0),"") | J21: =IFERROR(VLOOKUP(D21,DB!A:G,7,0),"") | L21: =IFERROR(VLOOKUP(D21,DB!A:I,9,0),"")
B22: =IFERROR(VLOOKUP(D22,DB!A:K,11,0),"") | G22: =IFERROR(NOW()-F22,"-") -> 45931.081 | I22: =IFERROR(VLOOKUP(D22,DB!A:F,6,0),"") | J22: =IFERROR(VLOOKUP(D22,DB!A:G,7,0),"") | L22: =IFERROR(VLOOKUP(D22,DB!A:I,9,0),"")
B23: =IFERROR(VLOOKUP(D23,DB!A:K,11,0),"") | G23: =IFERROR(NOW()-F23,"-") -> 45931.081 | I23: =IFERROR(VLOOKUP(D23,DB!A:F,6,0),"") | J23: =IFERROR(VLOOKUP(D23,DB!A:G,7,0),"") | L23: =IFERROR(VLOOKUP(D23,DB!A:I,9,0),"")
B24: =IFERROR(VLOOKUP(D24,DB!A:K,11,0),"") | G24: =IFERROR(NOW()-F24,"-") -> 45931.081 | I24: =IFERROR(VLOOKUP(D24,DB!A:F,6,0),"") | J24: =IFERROR(VLOOKUP(D24,DB!A:G,7,0),"") | L24: =IFERROR(VLOOKUP(D24,DB!A:I,9,0),"")
B25: =IFERROR(VLOOKUP(D25,DB!A:K,11,0),"") | G25: =IFERROR(NOW()-F25,"-") -> 45931.081 | I25: =IFERROR(VLOOKUP(D25,DB!A:F,6,0),"") | J25: =IFERROR(VLOOKUP(D25,DB!A:G,7,0),"") | L25: =IFERROR(VLOOKUP(D25,DB!A:I,9,0),"")
B26: =IFERROR(VLOOKUP(D26,DB!A:K,11,0),"") | G26: =IFERROR(NOW()-F26,"-") -> 45931.081 | I26: =IFERROR(VLOOKUP(D26,DB!A:F,6,0),"") | J26: =IFERROR(VLOOKUP(D26,DB!A:G,7,0),"") | L26: =IFERROR(VLOOKUP(D26,DB!A:I,9,0),"")
B27: =IFERROR(VLOOKUP(D27,DB!A:K,11,0),"") | G27: =IFERROR(NOW()-F27,"-") -> 45931.081 | I27: =IFERROR(VLOOKUP(D27,DB!A:F,6,0),"") | J27: =IFERROR(VLOOKUP(D27,DB!A:G,7,0),"") | L27: =IFERROR(VLOOKUP(D27,DB!A:I,9,0),"")
B28: =IFERROR(VLOOKUP(D28,DB!A:K,11,0),"") | G28: =IFERROR(NOW()-F28,"-") -> 45931.081 | I28: =IFERROR(VLOOKUP(D28,DB!A:F,6,0),"") | J28: =IFERROR(VLOOKUP(D28,DB!A:G,7,0),"") | L28: =IFERROR(VLOOKUP(D28,DB!A:I,9,0),"")
B29: =IFERROR(VLOOKUP(D29,DB!A:K,11,0),"") | G29: =IFERROR(NOW()-F29,"-") -> 45931.081 | I29: =IFERROR(VLOOKUP(D29,DB!A:F,6,0),"") | J29: =IFERROR(VLOOKUP(D29,DB!A:G,7,0),"") | L29: =IFERROR(VLOOKUP(D29,DB!A:I,9,0),"")
B30: =IFERROR(VLOOKUP(D30,DB!A:K,11,0),"") | G30: =IFERROR(NOW()-F30,"-") -> 45931.081 | I30: =IFERROR(VLOOKUP(D30,DB!A:F,6,0),"") | J30: =IFERROR(VLOOKUP(D30,DB!A:G,7,0),"") | L30: =IFERROR(VLOOKUP(D30,DB!A:I,9,0),"")
... B1238: =IFERROR(VLOOKUP(D1238,DB!A:K,11,0),"") | G1238: =IFERROR(NOW()-F1238,"-") -> 45931.081 | I1238: =IFERROR(VLOOKUP(D1238,DB!A:F,6,0),"") | J1238: =IFERROR(VLOOKUP(D1238,DB!A:G,7,0),"") | L1238: =IFERROR(VLOOKUP(D1238,DB!A:I,9,0),"")

Sheet R4
A1: PCM | B1: Region | C1: Count sites | D1: Hub Site | E1: Fault Level | F1: PCM Created At | G1: Elapsed Duration(Hrs) | H1: Creat Fault First Time Occured | I1: Power Source | J1: Battery Backup Status | K1: EM Field Feedback | L1: Site Owner
A2: PCM-20250215-00000830 | B2: =IFERROR(VLOOKUP(D2,DB!A:K,11,0),"") -> R4 | C2: 1 | D2: MKJD0649 | E2: Major | F2: 45703.481 | G2: =IFERROR(NOW()-F2,"") -> 227.60041 | H2: 45703.475 | I2: =IFERROR(VLOOKUP(D2,DB!A:F,6,0),"") -> SCECO | J2: =IFERROR(VLOOKUP(D2,DB!A:G,7,0),"") -> Dead | K2: LTE site still down and site located in aramco area access issue need special permission | L2: =IFERROR(VLOOKUP(D2,DB!A:I,9,0),"") -> Latis
A3: PCM-20250930-00002232 | B3: =IFERROR(VLOOKUP(D3,DB!A:K,11,0),"") -> R4 | C3: 2 | D3: jed2004 | E3: Major | F3: 45930.89 | G3: =IFERROR(NOW()-F3,"") -> 0.19085231 | H3: 45930.847 | I3: =IFERROR(VLOOKUP(D3,DB!A:F,6,0),"") -> SCECO | J3: =IFERROR(VLOOKUP(D3,DB!A:G,7,0),"") -> In progress | K3: access issue as team found Hotel closed by municipality and no one is available there | L3: =IFERROR(VLOOKUP(D3,DB!A:I,9,0),"") -> Latis
B4: =IFERROR(VLOOKUP(D4,DB!A:K,11,0),"") | G4: =IFERROR(NOW()-F4,"") -> 45931.081 | I4: =IFERROR(VLOOKUP(D4,DB!A:F,6,0),"") | J4: =IFERROR(VLOOKUP(D4,DB!A:G,7,0),"") | L4: =IFERROR(VLOOKUP(D4,DB!A:I,9,0),"")
B5: =IFERROR(VLOOKUP(D5,DB!A:K,11,0),"") | G5: =IFERROR(NOW()-F5,"") -> 45931.081 | I5: =IFERROR(VLOOKUP(D5,DB!A:F,6,0),"") | J5: =IFERROR(VLOOKUP(D5,DB!A:G,7,0),"") | L5: =IFERROR(VLOOKUP(D5,DB!A:I,9,0),"")
B6: =IFERROR(VLOOKUP(D6,DB!A:K,11,0),"") | G6: =IFERROR(NOW()-F6,"") -> 45931.081 | I6: =IFERROR(VLOOKUP(D6,DB!A:F,6,0),"") | J6: =IFERROR(VLOOKUP(D6,DB!A:G,7,0),"") | L6: =IFERROR(VLOOKUP(D6,DB!A:I,9,0),"")
B7: =IFERROR(VLOOKUP(D7,DB!A:K,11,0),"") | G7: =IFERROR(NOW()-F7,"") -> 45931.081 | I7: =IFERROR(VLOOKUP(D7,DB!A:F,6,0),"") | J7: =IFERROR(VLOOKUP(D7,DB!A:G,7,0),"") | L7: =IFERROR(VLOOKUP(D7,DB!A:I,9,0),"")
B8: =IFERROR(VLOOKUP(D8,DB!A:K,11,0),"") | G8: =IFERROR(NOW()-F8,"") -> 45931.081 | I8: =IFERROR(VLOOKUP(D8,DB!A:F,6,0),"") | J8: =IFERROR(VLOOKUP(D8,DB!A:G,7,0),"") | L8: =IFERROR(VLOOKUP(D8,DB!A:I,9,0),"")
B9: =IFERROR(VLOOKUP(D9,DB!A:K,11,0),"") | G9: =IFERROR(NOW()-F9,"") -> 45931.081 | I9: =IFERROR(VLOOKUP(D9,DB!A:F,6,0),"") | J9: =IFERROR(VLOOKUP(D9,DB!A:G,7,0),"") | L9: =IFERROR(VLOOKUP(D9,DB!A:I,9,0),"")
B10: =IFERROR(VLOOKUP(D10,DB!A:K,11,0),"") | G10: =IFERROR(NOW()-F10,"") -> 45931.081 | I10: =IFERROR(VLOOKUP(D10,DB!A:F,6,0),"") | J10: =IFERROR(VLOOKUP(D10,DB!A:G,7,0),"") | L10: =IFERROR(VLOOKUP(D10,DB!A:I,9,0),"")
B11: =IFERROR(VLOOKUP(D11,DB!A:K,11,0),"") | G11: =IFERROR(NOW()-F11,"") -> 45931.081 | I11: =IFERROR(VLOOKUP(D11,DB!A:F,6,0),"") | J11: =IFERROR(VLOOKUP(D11,DB!A:G,7,0),"") | L11: =IFERROR(VLOOKUP(D11,DB!A:I,9,0),"")
B12: =IFERROR(VLOOKUP(D12,DB!A:K,11,0),"") | G12: =IFERROR(NOW()-F12,"") -> 45931.081 | I12: =IFERROR(VLOOKUP(D12,DB!A:F,6,0),"") | J12: =IFERROR(VLOOKUP(D12,DB!A:G,7,0),"") | L12: =IFERROR(VLOOKUP(D12,DB!A:I,9,0),"")
B13: =IFERROR(VLOOKUP(D13,DB!A:K,11,0),"") | G13: =IFERROR(NOW()-F13,"") -> 45931.081 | I13: =IFERROR(VLOOKUP(D13,DB!A:F,6,0),"") | J13: =IFERROR(VLOOKUP(D13,DB!A:G,7,0),"") | L13: =IFERROR(VLOOKUP(D13,DB!A:I,9,0),"")
B14: =IFERROR(VLOOKUP(D14,DB!A:K,11,0),"") | G14: =IFERROR(NOW()-F14,"") -> 45931.081 | I14: =IFERROR(VLOOKUP(D14,DB!A:F,6,0),"") | J14: =IFERROR(VLOOKUP(D14,DB!A:G,7,0),"") | L14: =IFERROR(VLOOKUP(D14,DB!A:I,9,0),"")
B15: =IFERROR(VLOOKUP(D15,DB!A:K,11,0),"") | G15: =IFERROR(NOW()-F15,"") -> 45931.081 | I15: =IFERROR(VLOOKUP(D15,DB!A:F,6,0),"") | J15: =IFERROR(VLOOKUP(D15,DB!A:G,7,0),"") | L15: =IFERROR(VLOOKUP(D15,DB!A:I,9,0),"")
... B21: =IFERROR(VLOOKUP(D21,DB!A:K,11,0),"") | G21: =IFERROR(NOW()-F21,"") -> 45931.081 | I21: =IFERROR(VLOOKUP(D21,DB!A:F,6,0),"") | J21: =IFERROR(VLOOKUP(D21,DB!A:G,7,0),"") | L21: =IFERROR(VLOOKUP(D21,DB!A:I,9,0),"")
B22: =IFERROR(VLOOKUP(D23,DB!A:K,11,0),"") | G22: =IFERROR(NOW()-F22,"") -> 45931.081 | I22: =IFERROR(VLOOKUP(D23,DB!A:F,6,0),"") | J22: =IFERROR(VLOOKUP(D23,DB!A:G,7,0),"") | L22: =IFERROR(VLOOKUP(D23,DB!A:I,9,0),"")
B23: =IFERROR(VLOOKUP(#REF!,DB!A:K,11,0),"") | G23: =IFERROR(NOW()-F23,"") -> 45931.081 | I23: =IFERROR(VLOOKUP(#REF!,DB!A:F,6,0),"") | J23: =IFERROR(VLOOKUP(#REF!,DB!A:G,7,0),"") | L23: =IFERROR(VLOOKUP(#REF!,DB!A:I,9,0),"")
B24: =IFERROR(VLOOKUP(D24,DB!A:K,11,0),"") | G24: =IFERROR(NOW()-F24,"") -> 45931.081 | I24: =IFERROR(VLOOKUP(D24,DB!A:F,6,0),"") | J24: =IFERROR(VLOOKUP(D24,DB!A:G,7,0),"") | L24: =IFERROR(VLOOKUP(D24,DB!A:I,9,0),"")
B25: =IFERROR(VLOOKUP(D25,DB!A:K,11,0),"") | G25: =IFERROR(NOW()-F25,"") -> 45931.081 | I25: =IFERROR(VLOOKUP(D25,DB!A:F,6,0),"") | J25: =IFERROR(VLOOKUP(D25,DB!A:G,7,0),"") | L25: =IFERROR(VLOOKUP(D25,DB!A:I,9,0),"")
B26: =IFERROR(VLOOKUP(D26,DB!A:K,11,0),"") | G26: =IFERROR(NOW()-F26,"") -> 45931.081 | I26: =IFERROR(VLOOKUP(D26,DB!A:F,6,0),"") | J26: =IFERROR(VLOOKUP(D26,DB!A:G,7,0),"") | L26: =IFERROR(VLOOKUP(D26,DB!A:I,9,0),"")
B27: =IFERROR(VLOOKUP(D27,DB!A:K,11,0),"") | G27: =IFERROR(NOW()-F27,"") -> 45931.081 | I27: =IFERROR(VLOOKUP(D27,DB!A:F,6,0),"") | J27: =IFERROR(VLOOKUP(D27,DB!A:G,7,0),"") | L27: =IFERROR(VLOOKUP(D27,DB!A:I,9,0),"")
B28: =IFERROR(VLOOKUP(D28,DB!A:K,11,0),"") | G28: =IFERROR(NOW()-F28,"") -> 45931.081 | I28: =IFERROR(VLOOKUP(D28,DB!A:F,6,0),"") | J28: =IFERROR(VLOOKUP(D28,DB!A:G,7,0),"") | L28: =IFERROR(VLOOKUP(D28,DB!A:I,9,0),"")
B29: =IFERROR(VLOOKUP(D29,DB!A:K,11,0),"") | G29: =IFERROR(NOW()-F29,"") -> 45931.081 | I29: =IFERROR(VLOOKUP(D29,DB!A:F,6,0),"") | J29: =IFERROR(VLOOKUP(D29,DB!A:G,7,0),"") | L29: =IFERROR(VLOOKUP(D29,DB!A:I,9,0),"")
B30: =IFERROR(VLOOKUP(D30,DB!A:K,11,0),"") | G30: =IFERROR(NOW()-F30,"") -> 45931.081 | I30: =IFERROR(VLOOKUP(D30,DB!A:F,6,0),"") | J30: =IFERROR(VLOOKUP(D30,DB!A:G,7,0),"") | L30: =IFERROR(VLOOKUP(D30,DB!A:I,9,0),"")
B31: =IFERROR(VLOOKUP(D31,DB!A:K,11,0),"") | G31: =IFERROR(NOW()-F31,"") -> 45931.081 | I31: =IFERROR(VLOOKUP(D31,DB!A:F,6,0),"") | J31: =IFERROR(VLOOKUP(D31,DB!A:G,7,0),"") | L31: =IFERROR(VLOOKUP(D31,DB!A:I,9,0),"")
B32: =IFERROR(VLOOKUP(D32,DB!A:K,11,0),"") | G32: =IFERROR(NOW()-F32,"") -> 45931.081 | I32: =IFERROR(VLOOKUP(D32,DB!A:F,6,0),"") | J32: =IFERROR(VLOOKUP(D32,DB!A:G,7,0),"") | L32: =IFERROR(VLOOKUP(D32,DB!A:I,9,0),"")
B33: =IFERROR(VLOOKUP(D33,DB!A:K,11,0),"") | G33: =IFERROR(NOW()-F33,"") -> 45931.081 | I33: =IFERROR(VLOOKUP(D33,DB!A:F,6,0),"") | J33: =IFERROR(VLOOKUP(D33,DB!A:G,7,0),"") | L33: =IFERROR(VLOOKUP(D33,DB!A:I,9,0),"")
B34: =IFERROR(VLOOKUP(D34,DB!A:K,11,0),"") | G34: =IFERROR(NOW()-F34,"") -> 45931.081 | I34: =IFERROR(VLOOKUP(D34,DB!A:F,6,0),"") | J34: =IFERROR(VLOOKUP(D34,DB!A:G,7,0),"") | L34: =IFERROR(VLOOKUP(D34,DB!A:I,9,0),"")
B35: =IFERROR(VLOOKUP(D35,DB!A:K,11,0),"") | G35: =IFERROR(NOW()-F35,"") -> 45931.081 | I35: =IFERROR(VLOOKUP(D35,DB!A:F,6,0),"") | J35: =IFERROR(VLOOKUP(D35,DB!A:G,7,0),"") | L35: =IFERROR(VLOOKUP(D35,DB!A:I,9,0),"")
B36: =IFERROR(VLOOKUP(D36,DB!A:K,11,0),"") | G36: =IFERROR(NOW()-F36,"") -> 45931.081 | I36: =IFERROR(VLOOKUP(D36,DB!A:F,6,0),"") | J36: =IFERROR(VLOOKUP(D36,DB!A:G,7,0),"") | L36: =IFERROR(VLOOKUP(D36,DB!A:I,9,0),"")

Sheet R5
A1: PCM | B1: Region | C1: Count sites | D1: Hub Site | E1: Fault Level | F1: PCM Created At | G1: Elapsed Duration(Hrs) | H1: Creat Fault First Time Occured | I1: Power Source | J1: Battery Backup Status | K1: EM Field Feedback | L1: Site Owner
A2: PCM-20250822-00001816 | B2: =IFERROR(VLOOKUP(D2,DB!A:K,11,0),"") -> R5 | C2: 3 | D2: AKR0339 | E2: Major | F2: 45891.832 | G2: =IFERROR(NOW()-F2,"-") -> 39.24907 | H2: 45891.79 | I2: =IFERROR(VLOOKUP(D2,DB!A:F,6,0),"") -> Generator-SG | J2: =IFERROR(VLOOKUP(D2,DB!A:G,7,0),"") -> Vandalized | K2: Team found Tower fall down | L2: =IFERROR(VLOOKUP(D2,DB!A:I,9,0),"") -> Latis
A3: PCM-20250926-00000245 | B3: =IFERROR(VLOOKUP(D3,DB!A:K,11,0),"") -> R5 | C3: 1 | D3: MAK0390 | E3: Critical | F3: 45926.189 | G3: =IFERROR(NOW()-F3,"-") -> 4.8922528 | H3: 45926.158 | I3: =IFERROR(VLOOKUP(D3,DB!A:F,6,0),"") -> SCECO | J3: =IFERROR(VLOOKUP(D3,DB!A:G,7,0),"") -> Good | K3: TE issue (No connection to unit) alarm active , TE team facing access issue as site located on hotel and closed by Judicial court | L3: =IFERROR(VLOOKUP(D3,DB!A:I,9,0),"") -> Latis
B4: =IFERROR(VLOOKUP(D4,DB!A:K,11,0),"") | G4: =IFERROR(NOW()-F4,"-") -> 45931.081 | I4: =IFERROR(VLOOKUP(D4,DB!A:F,6,0),"") | J4: =IFERROR(VLOOKUP(D4,DB!A:G,7,0),"") | L4: =IFERROR(VLOOKUP(D4,DB!A:I,9,0),"")
B5: =IFERROR(VLOOKUP(D5,DB!A:K,11,0),"") | G5: =IFERROR(NOW()-F5,"-") -> 45931.081 | I5: =IFERROR(VLOOKUP(D5,DB!A:F,6,0),"") | J5: =IFERROR(VLOOKUP(D5,DB!A:G,7,0),"") | L5: =IFERROR(VLOOKUP(D5,DB!A:I,9,0),"")
B6: =IFERROR(VLOOKUP(D6,DB!A:K,11,0),"") | G6: =IFERROR(NOW()-F6,"-") -> 45931.081 | I6: =IFERROR(VLOOKUP(D6,DB!A:F,6,0),"") | J6: =IFERROR(VLOOKUP(D6,DB!A:G,7,0),"") | L6: =IFERROR(VLOOKUP(D6,DB!A:I,9,0),"")
B7: =IFERROR(VLOOKUP(D7,DB!A:K,11,0),"") | G7: =IFERROR(NOW()-F7,"-") -> 45931.081 | I7: =IFERROR(VLOOKUP(D7,DB!A:F,6,0),"") | J7: =IFERROR(VLOOKUP(D7,DB!A:G,7,0),"") | L7: =IFERROR(VLOOKUP(D7,DB!A:I,9,0),"")
B8: =IFERROR(VLOOKUP(D8,DB!A:K,11,0),"") | G8: =IFERROR(NOW()-F8,"-") -> 45931.081 | I8: =IFERROR(VLOOKUP(D8,DB!A:F,6,0),"") | J8: =IFERROR(VLOOKUP(D8,DB!A:G,7,0),"") | L8: =IFERROR(VLOOKUP(D8,DB!A:I,9,0),"")
B9: =IFERROR(VLOOKUP(D9,DB!A:K,11,0),"") | G9: =IFERROR(NOW()-F9,"-") -> 45931.081 | I9: =IFERROR(VLOOKUP(D9,DB!A:F,6,0),"") | J9: =IFERROR(VLOOKUP(D9,DB!A:G,7,0),"") | L9: =IFERROR(VLOOKUP(D9,DB!A:I,9,0),"")
B10: =IFERROR(VLOOKUP(D10,DB!A:K,11,0),"") | G10: =IFERROR(NOW()-F10,"-") -> 45931.081 | I10: =IFERROR(VLOOKUP(D10,DB!A:F,6,0),"") | J10: =IFERROR(VLOOKUP(D10,DB!A:G,7,0),"") | L10: =IFERROR(VLOOKUP(D10,DB!A:I,9,0),"")
B11: =IFERROR(VLOOKUP(D11,DB!A:K,11,0),"") | G11: =IFERROR(NOW()-F11,"-") -> 45931.081 | I11: =IFERROR(VLOOKUP(D11,DB!A:F,6,0),"") | J11: =IFERROR(VLOOKUP(D11,DB!A:G,7,0),"") | L11: =IFERROR(VLOOKUP(D11,DB!A:I,9,0),"")
B12: =IFERROR(VLOOKUP(D12,DB!A:K,11,0),"") | G12: =IFERROR(NOW()-F12,"-") -> 45931.081 | I12: =IFERROR(VLOOKUP(D12,DB!A:F,6,0),"") | J12: =IFERROR(VLOOKUP(D12,DB!A:G,7,0),"") | L12: =IFERROR(VLOOKUP(D12,DB!A:I,9,0),"")
B13: =IFERROR(VLOOKUP(D13,DB!A:K,11,0),"") | G13: =IFERROR(NOW()-F13,"-") -> 45931.081 | I13: =IFERROR(VLOOKUP(D13,DB!A:F,6,0),"") | J13: =IFERROR(VLOOKUP(D13,DB!A:G,7,0),"") | L13: =IFERROR(VLOOKUP(D13,DB!A:I,9,0),"")
B14: =IFERROR(VLOOKUP(D14,DB!A:K,11,0),"") | G14: =IFERROR(NOW()-F14,"-") -> 45931.081 | I14: =IFERROR(VLOOKUP(D14,DB!A:F,6,0),"") | J14: =IFERROR(VLOOKUP(D14,DB!A:G,7,0),"") | L14: =IFERROR(VLOOKUP(D14,DB!A:I,9,0),"")
B15: =IFERROR(VLOOKUP(D15,DB!A:K,11,0),"") | G15: =IFERROR(NOW()-F15,"-") -> 45931.081 | I15: =IFERROR(VLOOKUP(D15,DB!A:F,6,0),"") | J15: =IFERROR(VLOOKUP(D15,DB!A:G,7,0),"") | L15: =IFERROR(VLOOKUP(D15,DB!A:I,9,0),"")
... B242: =IFERROR(VLOOKUP(D242,DB!A:K,11,0),"") | G242: =IFERROR(NOW()-F242,"-") -> 45931.081 | I242: =IFERROR(VLOOKUP(D242,DB!A:F,6,0),"") | J242: =IFERROR(VLOOKUP(D242,DB!A:G,7,0),"") | L242: =IFERROR(VLOOKUP(D242,DB!A:I,9,0),"")

Sheet R6
A1: PCM | B1: Region | C1: Count sites | D1: Hub Site | E1: Fault Level | F1: PCM Created At | G1: Elapsed Duration(Hrs) | H1: Creat Fault First Time Occured | I1: Power Source | J1: Battery Backup Status | K1: EM Field Feedback | L1: Site Owner
A2: PCM-20250929-00001062 | B2: R6 | C2: 1 | D2: MRD0092 | E2: Minor | F2: 45929.144 | G2: =IFERROR(NOW()-F2,"-") -> 1.9374148 | H2: 45929.455 | I2: =IFERROR(VLOOKUP(D2,DB!A:F,6,0),"") -> SCECO | J2: =IFERROR(VLOOKUP(D2,DB!A:G,7,0),"") -> In progress | K2: Cell down due to obsolete module shortage ( issue esclated to LATIS team and waiting their support to arrange modules) | L2: =IFERROR(VLOOKUP(D2,DB!A:I,9,0),"") -> Latis
A3: PCM-20250926-00001863 | B3: R6 | C3: 1 | D3: MHL0139 | E3: Minor | F3: 45926.773 | G3: =IFERROR(NOW()-F3,"-") -> 4.3082829 | H3: 45927.449 | I3: =IFERROR(VLOOKUP(D3,DB!A:F,6,0),"") -> SCECO | J3: =IFERROR(VLOOKUP(D3,DB!A:G,7,0),"") -> Weak | K3: Cell down due to obsolete module shortage ( issue esclated to LATIS team and waiting their support to arrange modules) | L3: =IFERROR(VLOOKUP(D3,DB!A:I,9,0),"") -> Latis
A4: PCM-20250927-00000195 | B4: R6 | C4: 1 | D4: BLQ0112 | E4: Minor | F4: 45927.118 | G4: =IFERROR(NOW()-F4,"-") -> 3.9635838 | H4: 45926.848 | I4: =IFERROR(VLOOKUP(D4,DB!A:F,6,0),"") -> SCECO | J4: =IFERROR(VLOOKUP(D4,DB!A:G,7,0),"") -> Dead | K4: Cell down due to obsolete module shortage ( issue esclated to LATIS team and waiting their support to arrange modules) | L4: =IFERROR(VLOOKUP(D4,DB!A:I,9,0),"") -> Latis
A5: PCM-20250930-00001960 | B5: =IFERROR(VLOOKUP(D5,DB!A:K,11,0),"") -> R6 | C5: 2 | D5: SUL9467 | E5: Major | F5: 45930.73 | G5: =IFERROR(NOW()-F5,"-") -> 0.35111852 | H5: 45930.747 | I5: =IFERROR(VLOOKUP(D5,DB!A:F,6,0),"") -> Generator-SG | J5: =IFERROR(VLOOKUP(D5,DB!A:G,7,0),"") -> Vandalized | K5: Site has Access issue at Night | L5: =IFERROR(VLOOKUP(D5,DB!A:I,9,0),"") -> Latis
A6: PCM-20251001-00000096 | B6: =IFERROR(VLOOKUP(D6,DB!A:K,11,0),"") -> R6 | C6: 2 | D6: JIZ0100 | E6: Major | F6: 45931.054 | G6: =IFERROR(NOW()-F6,"-") -> 0.026847685 | H6: 45931.012 | I6: =IFERROR(VLOOKUP(D6,DB!A:F,6,0),"") -> SCECO | J6: =IFERROR(VLOOKUP(D6,DB!A:G,7,0),"") -> Dead | K6: site has access issue due to site located at hotel and team At hotel gate trying to getting access and mandoob now engaged | L6: =IFERROR(VLOOKUP(D6,DB!A:I,9,0),"") -> Latis
A7: PCM-20251001-00000094 | B7: =IFERROR(VLOOKUP(D7,DB!A:K,11,0),"") -> R6 | C7: 3 | D7: DRB0904 | E7: Major | F7: 45931.053 | G7: =IFERROR(NOW()-F7,"-") -> 0.027762037 | H7: 45931.034 | I7: =IFERROR(VLOOKUP(D7,DB!A:F,6,0),"") -> Generator-SG | J7: =IFERROR(VLOOKUP(D7,DB!A:G,7,0),"") -> Dead | K7: ETA 50 mins | L7: =IFERROR(VLOOKUP(D7,DB!A:I,9,0),"") -> Latis
B8: =IFERROR(VLOOKUP(D8,DB!A:K,11,0),"") | G8: =IFERROR(NOW()-F8,"-") -> 45931.081 | I8: =IFERROR(VLOOKUP(D8,DB!A:F,6,0),"") | J8: =IFERROR(VLOOKUP(D8,DB!A:G,7,0),"") | L8: =IFERROR(VLOOKUP(D8,DB!A:I,9,0),"")
B9: =IFERROR(VLOOKUP(D9,DB!A:K,11,0),"") | G9: =IFERROR(NOW()-F9,"-") -> 45931.081 | I9: =IFERROR(VLOOKUP(D9,DB!A:F,6,0),"") | J9: =IFERROR(VLOOKUP(D9,DB!A:G,7,0),"") | L9: =IFERROR(VLOOKUP(D9,DB!A:I,9,0),"")
B10: =IFERROR(VLOOKUP(D10,DB!A:K,11,0),"") | G10: =IFERROR(NOW()-F10,"-") -> 45931.081 | I10: =IFERROR(VLOOKUP(D10,DB!A:F,6,0),"") | J10: =IFERROR(VLOOKUP(D10,DB!A:G,7,0),"") | L10: =IFERROR(VLOOKUP(D10,DB!A:I,9,0),"")
B11: =IFERROR(VLOOKUP(D11,DB!A:K,11,0),"") | G11: =IFERROR(NOW()-F11,"-") -> 45931.081 | I11: =IFERROR(VLOOKUP(D11,DB!A:F,6,0),"") | J11: =IFERROR(VLOOKUP(D11,DB!A:G,7,0),"") | L11: =IFERROR(VLOOKUP(D11,DB!A:I,9,0),"")
B12: =IFERROR(VLOOKUP(D12,DB!A:K,11,0),"") | G12: =IFERROR(NOW()-F12,"-") -> 45931.081 | I12: =IFERROR(VLOOKUP(D12,DB!A:F,6,0),"") | J12: =IFERROR(VLOOKUP(D12,DB!A:G,7,0),"") | L12: =IFERROR(VLOOKUP(D12,DB!A:I,9,0),"")
B13: =IFERROR(VLOOKUP(D13,DB!A:K,11,0),"") | G13: =IFERROR(NOW()-F13,"-") -> 45931.081 | I13: =IFERROR(VLOOKUP(D13,DB!A:F,6,0),"") | J13: =IFERROR(VLOOKUP(D13,DB!A:G,7,0),"") | L13: =IFERROR(VLOOKUP(D13,DB!A:I,9,0),"")
B14: =IFERROR(VLOOKUP(D14,DB!A:K,11,0),"") | G14: =IFERROR(NOW()-F14,"-") -> 45931.081 | I14: =IFERROR(VLOOKUP(D14,DB!A:F,6,0),"") | J14: =IFERROR(VLOOKUP(D14,DB!A:G,7,0),"") | L14: =IFERROR(VLOOKUP(D14,DB!A:I,9,0),"")
B15: =IFERROR(VLOOKUP(D15,DB!A:K,11,0),"") | G15: =IFERROR(NOW()-F15,"-") -> 45931.081 | I15: =IFERROR(VLOOKUP(D15,DB!A:F,6,0),"") | J15: =IFERROR(VLOOKUP(D15,DB!A:G,7,0),"") | L15: =IFERROR(VLOOKUP(D15,DB!A:I,9,0),"")
B16: =IFERROR(VLOOKUP(D16,DB!A:K,11,0),"") | G16: =IFERROR(NOW()-F16,"-") -> 45931.081 | I16: =IFERROR(VLOOKUP(D16,DB!A:F,6,0),"") | J16: =IFERROR(VLOOKUP(D16,DB!A:G,7,0),"") | L16: =IFERROR(VLOOKUP(D16,DB!A:I,9,0),"")
B17: =IFERROR(VLOOKUP(D17,DB!A:K,11,0),"") | G17: =IFERROR(NOW()-F17,"-") -> 45931.081 | I17: =IFERROR(VLOOKUP(D17,DB!A:F,6,0),"") | J17: =IFERROR(VLOOKUP(D17,DB!A:G,7,0),"") | L17: =IFERROR(VLOOKUP(D17,DB!A:I,9,0),"")
B18: =IFERROR(VLOOKUP(D18,DB!A:K,11,0),"") | G18: =IFERROR(NOW()-F18,"-") -> 45931.081 | I18: =IFERROR(VLOOKUP(D18,DB!A:F,6,0),"") | J18: =IFERROR(VLOOKUP(D18,DB!A:G,7,0),"") | L18: =IFERROR(VLOOKUP(D18,DB!A:I,9,0),"")
B19: =IFERROR(VLOOKUP(D19,DB!A:K,11,0),"") | G19: =IFERROR(NOW()-F19,"-") -> 45931.081 | I19: =IFERROR(VLOOKUP(D19,DB!A:F,6,0),"") | J19: =IFERROR(VLOOKUP(D19,DB!A:G,7,0),"") | L19: =IFERROR(VLOOKUP(D19,DB!A:I,9,0),"")
... B349: =IFERROR(VLOOKUP(D349,DB!A:K,11,0),"") | G349: =IFERROR(NOW()-F349,"-") -> 45931.081 | I349: =IFERROR(VLOOKUP(D349,DB!A:F,6,0),"") | J349: =IFERROR(VLOOKUP(D349,DB!A:G,7,0),"") | L349: =IFERROR(VLOOKUP(D349,DB!A:I,9,0),"")
